{"name": "Проверяем невозможность обновления данных у неавторизованного пользователя", "status": "passed", "description": "Проверяем, что возвращается ошибка при изменении данных у неавторизованного пользователя", "start": 1752511669410, "stop": 1752511669623, "uuid": "a4d7ebc5-8975-497a-92a4-22a914468857", "historyId": "244facbabebc29310b7013a5e3a55b4d", "testCaseId": "244facbabebc29310b7013a5e3a55b4d", "fullName": "tests.test_update_user_data.TestUpdateUserData#test_update_user_data_to_not_auth_user_error", "labels": [{"name": "parentSuite", "value": "tests"}, {"name": "suite", "value": "test_update_user_data"}, {"name": "subSuite", "value": "TestUpdateUserData"}, {"name": "host", "value": "DESKTOP-PM8THT8"}, {"name": "thread", "value": "13836-MainThread"}, {"name": "framework", "value": "pytest"}, {"name": "language", "value": "cpython3"}, {"name": "package", "value": "tests.test_update_user_data"}]}